[2024-07-20T13:03:02.822+0000] {local_task_job_runner.py:120} INFO - ::group::Pre task execution logs
[2024-07-20T13:03:02.842+0000] {taskinstance.py:2076} INFO - Dependencies all met for dep_context=non-requeueable deps ti=<TaskInstance: etl_reddit_pipeline.s3_upload manual__2024-07-20T13:02:55.932041+00:00 [queued]>
[2024-07-20T13:03:02.848+0000] {taskinstance.py:2076} INFO - Dependencies all met for dep_context=requeueable deps ti=<TaskInstance: etl_reddit_pipeline.s3_upload manual__2024-07-20T13:02:55.932041+00:00 [queued]>
[2024-07-20T13:03:02.848+0000] {taskinstance.py:2306} INFO - Starting attempt 1 of 1
[2024-07-20T13:03:02.857+0000] {taskinstance.py:2330} INFO - Executing <Task(PythonOperator): s3_upload> on 2024-07-20 13:02:55.932041+00:00
[2024-07-20T13:03:02.863+0000] {standard_task_runner.py:64} INFO - Started process 96 to run task
[2024-07-20T13:03:02.866+0000] {standard_task_runner.py:90} INFO - Running: ['airflow', 'tasks', 'run', 'etl_reddit_pipeline', 's3_upload', 'manual__2024-07-20T13:02:55.932041+00:00', '--job-id', '15', '--raw', '--subdir', 'DAGS_FOLDER/reddit_dag.py', '--cfg-path', '/tmp/tmpodjjljha']
[2024-07-20T13:03:02.867+0000] {standard_task_runner.py:91} INFO - Job 15: Subtask s3_upload
[2024-07-20T13:03:02.902+0000] {task_command.py:426} INFO - Running <TaskInstance: etl_reddit_pipeline.s3_upload manual__2024-07-20T13:02:55.932041+00:00 [running]> on host 3fae78c04921
[2024-07-20T13:03:02.964+0000] {taskinstance.py:2648} INFO - Exporting env vars: AIRFLOW_CTX_DAG_OWNER='nopega' AIRFLOW_CTX_DAG_ID='etl_reddit_pipeline' AIRFLOW_CTX_TASK_ID='s3_upload' AIRFLOW_CTX_EXECUTION_DATE='2024-07-20T13:02:55.932041+00:00' AIRFLOW_CTX_TRY_NUMBER='1' AIRFLOW_CTX_DAG_RUN_ID='manual__2024-07-20T13:02:55.932041+00:00'
[2024-07-20T13:03:02.965+0000] {taskinstance.py:430} INFO - ::endgroup::
[2024-07-20T13:03:05.186+0000] {logging_mixin.py:188} INFO - The AWS Access Key Id you provided does not exist in our records.
[2024-07-20T13:03:05.333+0000] {taskinstance.py:441} INFO - ::group::Post task execution logs
[2024-07-20T13:03:05.333+0000] {taskinstance.py:2905} ERROR - Task failed with exception
Traceback (most recent call last):
  File "/home/airflow/.local/lib/python3.10/site-packages/s3fs/core.py", line 723, in _lsdir
    async for c in self._iterdir(
  File "/home/airflow/.local/lib/python3.10/site-packages/s3fs/core.py", line 773, in _iterdir
    async for i in it:
  File "/home/airflow/.local/lib/python3.10/site-packages/aiobotocore/paginate.py", line 30, in __anext__
    response = await self._make_request(current_kwargs)
  File "/home/airflow/.local/lib/python3.10/site-packages/aiobotocore/client.py", line 411, in _make_api_call
    raise error_class(parsed_response, operation_name)
botocore.exceptions.ClientError: An error occurred (InvalidAccessKeyId) when calling the ListObjectsV2 operation: The AWS Access Key Id you provided does not exist in our records.

The above exception was the direct cause of the following exception:

Traceback (most recent call last):
  File "/home/airflow/.local/lib/python3.10/site-packages/airflow/models/taskinstance.py", line 465, in _execute_task
    result = _execute_callable(context=context, **execute_callable_kwargs)
  File "/home/airflow/.local/lib/python3.10/site-packages/airflow/models/taskinstance.py", line 432, in _execute_callable
    return execute_callable(context=context, **execute_callable_kwargs)
  File "/home/airflow/.local/lib/python3.10/site-packages/airflow/models/baseoperator.py", line 401, in wrapper
    return func(self, *args, **kwargs)
  File "/home/airflow/.local/lib/python3.10/site-packages/airflow/operators/python.py", line 235, in execute
    return_value = self.execute_callable()
  File "/home/airflow/.local/lib/python3.10/site-packages/airflow/operators/python.py", line 252, in execute_callable
    return self.python_callable(*self.op_args, **self.op_kwargs)
  File "/opt/airflow/pipelines/aws_s3_pipeline.py", line 9, in upload_s3_pipeline
    upload_to_s3(s3,file_path,AWS_BUCKET_NAME,file_path.split('/')[-1])
  File "/opt/airflow/etls/aws_etl.py", line 26, in upload_to_s3
    s3.put(file_path,bucket+'/raw/'+s3_file_name)
  File "/home/airflow/.local/lib/python3.10/site-packages/fsspec/asyn.py", line 118, in wrapper
    return sync(self.loop, func, *args, **kwargs)
  File "/home/airflow/.local/lib/python3.10/site-packages/fsspec/asyn.py", line 103, in sync
    raise return_result
  File "/home/airflow/.local/lib/python3.10/site-packages/fsspec/asyn.py", line 56, in _runner
    result[0] = await coro
  File "/home/airflow/.local/lib/python3.10/site-packages/fsspec/asyn.py", line 561, in _put
    trailing_sep(rpath) or await self._isdir(rpath)
  File "/home/airflow/.local/lib/python3.10/site-packages/s3fs/core.py", line 1483, in _isdir
    return bool(await self._lsdir(path))
  File "/home/airflow/.local/lib/python3.10/site-packages/s3fs/core.py", line 736, in _lsdir
    raise translate_boto_error(e)
PermissionError: The AWS Access Key Id you provided does not exist in our records.
[2024-07-20T13:03:05.346+0000] {taskinstance.py:1206} INFO - Marking task as FAILED. dag_id=etl_reddit_pipeline, task_id=s3_upload, run_id=manual__2024-07-20T13:02:55.932041+00:00, execution_date=20240720T130255, start_date=20240720T130302, end_date=20240720T130305
[2024-07-20T13:03:05.355+0000] {standard_task_runner.py:110} ERROR - Failed to execute job 15 for task s3_upload (The AWS Access Key Id you provided does not exist in our records.; 96)
[2024-07-20T13:03:05.404+0000] {local_task_job_runner.py:243} INFO - Task exited with return code 1
[2024-07-20T13:03:05.420+0000] {taskinstance.py:3503} INFO - 0 downstream tasks scheduled from follow-on schedule check
[2024-07-20T13:03:05.421+0000] {local_task_job_runner.py:222} INFO - ::endgroup::
