[2024-07-20T13:00:31.825+0000] {local_task_job_runner.py:120} INFO - ::group::Pre task execution logs
[2024-07-20T13:00:31.844+0000] {taskinstance.py:2076} INFO - Dependencies all met for dep_context=non-requeueable deps ti=<TaskInstance: etl_reddit_pipeline.s3_upload manual__2024-07-20T13:00:26.617367+00:00 [queued]>
[2024-07-20T13:00:31.849+0000] {taskinstance.py:2076} INFO - Dependencies all met for dep_context=requeueable deps ti=<TaskInstance: etl_reddit_pipeline.s3_upload manual__2024-07-20T13:00:26.617367+00:00 [queued]>
[2024-07-20T13:00:31.850+0000] {taskinstance.py:2306} INFO - Starting attempt 1 of 1
[2024-07-20T13:00:31.860+0000] {taskinstance.py:2330} INFO - Executing <Task(PythonOperator): s3_upload> on 2024-07-20 13:00:26.617367+00:00
[2024-07-20T13:00:31.865+0000] {standard_task_runner.py:64} INFO - Started process 75 to run task
[2024-07-20T13:00:31.868+0000] {standard_task_runner.py:90} INFO - Running: ['airflow', 'tasks', 'run', 'etl_reddit_pipeline', 's3_upload', 'manual__2024-07-20T13:00:26.617367+00:00', '--job-id', '9', '--raw', '--subdir', 'DAGS_FOLDER/reddit_dag.py', '--cfg-path', '/tmp/tmpn77cjw0w']
[2024-07-20T13:00:31.870+0000] {standard_task_runner.py:91} INFO - Job 9: Subtask s3_upload
[2024-07-20T13:00:31.906+0000] {task_command.py:426} INFO - Running <TaskInstance: etl_reddit_pipeline.s3_upload manual__2024-07-20T13:00:26.617367+00:00 [running]> on host 3fae78c04921
[2024-07-20T13:00:31.964+0000] {taskinstance.py:2648} INFO - Exporting env vars: AIRFLOW_CTX_DAG_OWNER='nopega' AIRFLOW_CTX_DAG_ID='etl_reddit_pipeline' AIRFLOW_CTX_TASK_ID='s3_upload' AIRFLOW_CTX_EXECUTION_DATE='2024-07-20T13:00:26.617367+00:00' AIRFLOW_CTX_TRY_NUMBER='1' AIRFLOW_CTX_DAG_RUN_ID='manual__2024-07-20T13:00:26.617367+00:00'
[2024-07-20T13:00:31.965+0000] {taskinstance.py:430} INFO - ::endgroup::
[2024-07-20T13:00:31.983+0000] {logging_mixin.py:188} INFO - yes
[2024-07-20T13:00:31.983+0000] {logging_mixin.py:188} INFO - 'S3FileSystem' object has no attribute 'exist'
[2024-07-20T13:00:31.987+0000] {taskinstance.py:441} INFO - ::group::Post task execution logs
[2024-07-20T13:00:31.987+0000] {taskinstance.py:2905} ERROR - Task failed with exception
Traceback (most recent call last):
  File "/home/airflow/.local/lib/python3.10/site-packages/airflow/models/taskinstance.py", line 465, in _execute_task
    result = _execute_callable(context=context, **execute_callable_kwargs)
  File "/home/airflow/.local/lib/python3.10/site-packages/airflow/models/taskinstance.py", line 432, in _execute_callable
    return execute_callable(context=context, **execute_callable_kwargs)
  File "/home/airflow/.local/lib/python3.10/site-packages/airflow/models/baseoperator.py", line 401, in wrapper
    return func(self, *args, **kwargs)
  File "/home/airflow/.local/lib/python3.10/site-packages/airflow/operators/python.py", line 235, in execute
    return_value = self.execute_callable()
  File "/home/airflow/.local/lib/python3.10/site-packages/airflow/operators/python.py", line 252, in execute_callable
    return self.python_callable(*self.op_args, **self.op_kwargs)
  File "/opt/airflow/pipelines/aws_s3_pipeline.py", line 9, in upload_s3_pipeline
    upload_to_s3(s3,file_path,AWS_BUCKET_NAME,file_path.split('/')[-1])
  File "/opt/airflow/etls/aws_etl.py", line 27, in upload_to_s3
    s3.put(file_path,bucket+'/raw/'+s3_file_name)
  File "/home/airflow/.local/lib/python3.10/site-packages/fsspec/asyn.py", line 118, in wrapper
    return sync(self.loop, func, *args, **kwargs)
  File "/home/airflow/.local/lib/python3.10/site-packages/fsspec/asyn.py", line 103, in sync
    raise return_result
  File "/home/airflow/.local/lib/python3.10/site-packages/fsspec/asyn.py", line 56, in _runner
    result[0] = await coro
  File "/home/airflow/.local/lib/python3.10/site-packages/fsspec/asyn.py", line 561, in _put
    trailing_sep(rpath) or await self._isdir(rpath)
  File "/home/airflow/.local/lib/python3.10/site-packages/s3fs/core.py", line 1483, in _isdir
    return bool(await self._lsdir(path))
  File "/home/airflow/.local/lib/python3.10/site-packages/s3fs/core.py", line 723, in _lsdir
    async for c in self._iterdir(
  File "/home/airflow/.local/lib/python3.10/site-packages/s3fs/core.py", line 754, in _iterdir
    await self.set_session()
  File "/home/airflow/.local/lib/python3.10/site-packages/s3fs/core.py", line 519, in set_session
    self.session = aiobotocore.session.AioSession(**self.kwargs)
TypeError: AioSession.__init__() got an unexpected keyword argument 'secrect'
[2024-07-20T13:00:32.002+0000] {taskinstance.py:1206} INFO - Marking task as FAILED. dag_id=etl_reddit_pipeline, task_id=s3_upload, run_id=manual__2024-07-20T13:00:26.617367+00:00, execution_date=20240720T130026, start_date=20240720T130031, end_date=20240720T130032
[2024-07-20T13:00:32.009+0000] {standard_task_runner.py:110} ERROR - Failed to execute job 9 for task s3_upload (AioSession.__init__() got an unexpected keyword argument 'secrect'; 75)
[2024-07-20T13:00:32.040+0000] {local_task_job_runner.py:243} INFO - Task exited with return code 1
[2024-07-20T13:00:32.052+0000] {taskinstance.py:3503} INFO - 0 downstream tasks scheduled from follow-on schedule check
[2024-07-20T13:00:32.054+0000] {local_task_job_runner.py:222} INFO - ::endgroup::
