[2024-07-20T13:01:04.090+0000] {local_task_job_runner.py:120} INFO - ::group::Pre task execution logs
[2024-07-20T13:01:04.109+0000] {taskinstance.py:2076} INFO - Dependencies all met for dep_context=non-requeueable deps ti=<TaskInstance: etl_reddit_pipeline.s3_upload manual__2024-07-20T13:00:59.793761+00:00 [queued]>
[2024-07-20T13:01:04.114+0000] {taskinstance.py:2076} INFO - Dependencies all met for dep_context=requeueable deps ti=<TaskInstance: etl_reddit_pipeline.s3_upload manual__2024-07-20T13:00:59.793761+00:00 [queued]>
[2024-07-20T13:01:04.115+0000] {taskinstance.py:2306} INFO - Starting attempt 1 of 1
[2024-07-20T13:01:04.123+0000] {taskinstance.py:2330} INFO - Executing <Task(PythonOperator): s3_upload> on 2024-07-20 13:00:59.793761+00:00
[2024-07-20T13:01:04.129+0000] {standard_task_runner.py:64} INFO - Started process 82 to run task
[2024-07-20T13:01:04.132+0000] {standard_task_runner.py:90} INFO - Running: ['airflow', 'tasks', 'run', 'etl_reddit_pipeline', 's3_upload', 'manual__2024-07-20T13:00:59.793761+00:00', '--job-id', '11', '--raw', '--subdir', 'DAGS_FOLDER/reddit_dag.py', '--cfg-path', '/tmp/tmpa8n7lygu']
[2024-07-20T13:01:04.134+0000] {standard_task_runner.py:91} INFO - Job 11: Subtask s3_upload
[2024-07-20T13:01:04.168+0000] {task_command.py:426} INFO - Running <TaskInstance: etl_reddit_pipeline.s3_upload manual__2024-07-20T13:00:59.793761+00:00 [running]> on host 3fae78c04921
[2024-07-20T13:01:04.224+0000] {taskinstance.py:2648} INFO - Exporting env vars: AIRFLOW_CTX_DAG_OWNER='nopega' AIRFLOW_CTX_DAG_ID='etl_reddit_pipeline' AIRFLOW_CTX_TASK_ID='s3_upload' AIRFLOW_CTX_EXECUTION_DATE='2024-07-20T13:00:59.793761+00:00' AIRFLOW_CTX_TRY_NUMBER='1' AIRFLOW_CTX_DAG_RUN_ID='manual__2024-07-20T13:00:59.793761+00:00'
[2024-07-20T13:01:04.225+0000] {taskinstance.py:430} INFO - ::endgroup::
[2024-07-20T13:01:04.242+0000] {logging_mixin.py:188} INFO - yes
[2024-07-20T13:01:04.243+0000] {logging_mixin.py:188} INFO - 'S3FileSystem' object has no attribute 'exist'
[2024-07-20T13:01:04.246+0000] {taskinstance.py:441} INFO - ::group::Post task execution logs
[2024-07-20T13:01:04.247+0000] {taskinstance.py:2905} ERROR - Task failed with exception
Traceback (most recent call last):
  File "/home/airflow/.local/lib/python3.10/site-packages/airflow/models/taskinstance.py", line 465, in _execute_task
    result = _execute_callable(context=context, **execute_callable_kwargs)
  File "/home/airflow/.local/lib/python3.10/site-packages/airflow/models/taskinstance.py", line 432, in _execute_callable
    return execute_callable(context=context, **execute_callable_kwargs)
  File "/home/airflow/.local/lib/python3.10/site-packages/airflow/models/baseoperator.py", line 401, in wrapper
    return func(self, *args, **kwargs)
  File "/home/airflow/.local/lib/python3.10/site-packages/airflow/operators/python.py", line 235, in execute
    return_value = self.execute_callable()
  File "/home/airflow/.local/lib/python3.10/site-packages/airflow/operators/python.py", line 252, in execute_callable
    return self.python_callable(*self.op_args, **self.op_kwargs)
  File "/opt/airflow/pipelines/aws_s3_pipeline.py", line 9, in upload_s3_pipeline
    upload_to_s3(s3,file_path,AWS_BUCKET_NAME,file_path.split('/')[-1])
  File "/opt/airflow/etls/aws_etl.py", line 27, in upload_to_s3
    s3.put(file_path,bucket+'/raw/'+s3_file_name)
  File "/home/airflow/.local/lib/python3.10/site-packages/fsspec/asyn.py", line 118, in wrapper
    return sync(self.loop, func, *args, **kwargs)
  File "/home/airflow/.local/lib/python3.10/site-packages/fsspec/asyn.py", line 103, in sync
    raise return_result
  File "/home/airflow/.local/lib/python3.10/site-packages/fsspec/asyn.py", line 56, in _runner
    result[0] = await coro
  File "/home/airflow/.local/lib/python3.10/site-packages/fsspec/asyn.py", line 561, in _put
    trailing_sep(rpath) or await self._isdir(rpath)
  File "/home/airflow/.local/lib/python3.10/site-packages/s3fs/core.py", line 1483, in _isdir
    return bool(await self._lsdir(path))
  File "/home/airflow/.local/lib/python3.10/site-packages/s3fs/core.py", line 723, in _lsdir
    async for c in self._iterdir(
  File "/home/airflow/.local/lib/python3.10/site-packages/s3fs/core.py", line 754, in _iterdir
    await self.set_session()
  File "/home/airflow/.local/lib/python3.10/site-packages/s3fs/core.py", line 519, in set_session
    self.session = aiobotocore.session.AioSession(**self.kwargs)
TypeError: AioSession.__init__() got an unexpected keyword argument 'secrect'
[2024-07-20T13:01:04.258+0000] {taskinstance.py:1206} INFO - Marking task as FAILED. dag_id=etl_reddit_pipeline, task_id=s3_upload, run_id=manual__2024-07-20T13:00:59.793761+00:00, execution_date=20240720T130059, start_date=20240720T130104, end_date=20240720T130104
[2024-07-20T13:01:04.266+0000] {standard_task_runner.py:110} ERROR - Failed to execute job 11 for task s3_upload (AioSession.__init__() got an unexpected keyword argument 'secrect'; 82)
[2024-07-20T13:01:04.304+0000] {local_task_job_runner.py:243} INFO - Task exited with return code 1
[2024-07-20T13:01:04.317+0000] {taskinstance.py:3503} INFO - 0 downstream tasks scheduled from follow-on schedule check
[2024-07-20T13:01:04.318+0000] {local_task_job_runner.py:222} INFO - ::endgroup::
